Workbook

Sheet Raw
A1: customerID | B1: gender | C1: SeniorCitizen | D1: Partner | E1: Dependents | F1: tenure | G1: PhoneService | H1: MultipleLines | I1: InternetService | J1: OnlineSecurity | K1: OnlineBackup | L1: DeviceProtection | M1: TechSupport | N1: StreamingTV | O1: StreamingMovies | P1: Contract | Q1: PaperlessBilling | R1: PaymentMethod | S1: MonthlyCharges | T1: TotalCharges | U1: Churn
A2: 7590-VHVEG | B2: Female | C2: 0 | D2: Yes | E2: No | F2: 1 | G2: No | H2: No phone service | I2: DSL | J2: No | K2: Yes | L2: No | M2: No | N2: No | O2: No | P2: Month-to-month | Q2: Yes | R2: Electronic check | S2: 29.85 | T2: 29.85 | U2: No
A3: 5575-GNVDE | B3: Male | C3: 0 | D3: No | E3: No | F3: 34 | G3: Yes | H3: No | I3: DSL | J3: Yes | K3: No | L3: Yes | M3: No | N3: No | O3: No | P3: One year | Q3: No | R3: Mailed check | S3: 56.95 | T3: 1889.5 | U3: No
A4: 3668-QPYBK | B4: Male | C4: 0 | D4: No | E4: No | F4: 2 | G4: Yes | H4: No | I4: DSL | J4: Yes | K4: Yes | L4: No | M4: No | N4: No | O4: No | P4: Month-to-month | Q4: Yes | R4: Mailed check | S4: 53.85 | T4: 108.15 | U4: Yes
A5: 7795-CFOCW | B5: Male | C5: 0 | D5: No | E5: No | F5: 45 | G5: No | H5: No phone service | I5: DSL | J5: Yes | K5: No | L5: Yes | M5: Yes | N5: No | O5: No | P5: One year | Q5: No | R5: Bank transfer (automatic) | S5: 42.3 | T5: 1840.75 | U5: No
A6: 9237-HQITU | B6: Female | C6: 0 | D6: No | E6: No | F6: 2 | G6: Yes | H6: No | I6: Fiber optic | J6: No | K6: No | L6: No | M6: No | N6: No | O6: No | P6: Month-to-month | Q6: Yes | R6: Electronic check | S6: 70.7 | T6: 151.65 | U6: Yes
A7: 9305-CDSKC | B7: Female | C7: 0 | D7: No | E7: No | F7: 8 | G7: Yes | H7: Yes | I7: Fiber optic | J7: No | K7: No | L7: Yes | M7: No | N7: Yes | O7: Yes | P7: Month-to-month | Q7: Yes | R7: Electronic check | S7: 99.65 | T7: 820.5 | U7: Yes
A8: 1452-KIOVK | B8: Male | C8: 0 | D8: No | E8: Yes | F8: 22 | G8: Yes | H8: Yes | I8: Fiber optic | J8: No | K8: Yes | L8: No | M8: No | N8: Yes | O8: No | P8: Month-to-month | Q8: Yes | R8: Credit card (automatic) | S8: 89.1 | T8: 1949.4 | U8: No
A9: 6713-OKOMC | B9: Female | C9: 0 | D9: No | E9: No | F9: 10 | G9: No | H9: No phone service | I9: DSL | J9: Yes | K9: No | L9: No | M9: No | N9: No | O9: No | P9: Month-to-month | Q9: No | R9: Mailed check | S9: 29.75 | T9: 301.9 | U9: No
A10: 7892-POOKP | B10: Female | C10: 0 | D10: Yes | E10: No | F10: 28 | G10: Yes | H10: Yes | I10: Fiber optic | J10: No | K10: No | L10: Yes | M10: Yes | N10: Yes | O10: Yes | P10: Month-to-month | Q10: Yes | R10: Electronic check | S10: 104.8 | T10: 3046.05 | U10: Yes
A11: 6388-TABGU | B11: Male | C11: 0 | D11: No | E11: Yes | F11: 62 | G11: Yes | H11: No | I11: DSL | J11: Yes | K11: Yes | L11: No | M11: No | N11: No | O11: No | P11: One year | Q11: No | R11: Bank transfer (automatic) | S11: 56.15 | T11: 3487.95 | U11: No
A12: 9763-GRSKD | B12: Male | C12: 0 | D12: Yes | E12: Yes | F12: 13 | G12: Yes | H12: No | I12: DSL | J12: Yes | K12: No | L12: No | M12: No | N12: No | O12: No | P12: Month-to-month | Q12: Yes | R12: Mailed check | S12: 49.95 | T12: 587.45 | U12: No
A13: 7469-LKBCI | B13: Male | C13: 0 | D13: No | E13: No | F13: 16 | G13: Yes | H13: No | I13: No | J13: No internet service | K13: No internet service | L13: No internet service | M13: No internet service | N13: No internet service | O13: No internet service | P13: Two year | Q13: No | R13: Credit card (automatic) | S13: 18.95 | T13: 326.8 | U13: No
... A489: 3649-JPUGY | B489: Male | C489: 0 | D489: No | E489: No | F489: 72 | G489: Yes | H489: Yes | I489: DSL | J489: No | K489: Yes | L489: Yes | M489: Yes | N489: Yes | O489: Yes | P489: Two year | Q489: Yes | R489: Bank transfer (automatic) | S489: 88.6 | T489: 6201.95 | U489: No
A490: 4472-LVYGI | B490: Female | C490: 0 | D490: Yes | E490: Yes | F490: 0 | G490: No | H490: No phone service | I490: DSL | J490: Yes | K490: No | L490: Yes | M490: Yes | N490: Yes | O490: No | P490: Two year | Q490: Yes | R490: Bank transfer (automatic) | S490: 52.55 | U490: No
A491: 8372-JUXUI | B491: Male | C491: 0 | D491: No | E491: Yes | F491: 1 | G491: Yes | H491: Yes | I491: Fiber optic | J491: No | K491: No | L491: No | M491: No | N491: No | O491: No | P491: Month-to-month | Q491: Yes | R491: Electronic check | S491: 74.35 | T491: 74.35 | U491: Yes
A492: 3552-CTCYF | B492: Male | C492: 0 | D492: Yes | E492: Yes | F492: 63 | G492: Yes | H492: Yes | I492: Fiber optic | J492: No | K492: Yes | L492: Yes | M492: No | N492: Yes | O492: Yes | P492: Two year | Q492: Yes | R492: Bank transfer (automatic) | S492: 104.8 | T492: 6597.25 | U492: No
A493: 6778-YSNIH | B493: Female | C493: 0 | D493: No | E493: No | F493: 2 | G493: Yes | H493: No | I493: DSL | J493: No | K493: Yes | L493: No | M493: No | N493: Yes | O493: No | P493: Month-to-month | Q493: Yes | R493: Electronic check | S493: 59 | T493: 114.15 | U493: No
A494: 0388-EOPEX | B494: Female | C494: 0 | D494: Yes | E494: No | F494: 2 | G494: Yes | H494: No | I494: Fiber optic | J494: Yes | K494: No | L494: No | M494: No | N494: No | O494: No | P494: Month-to-month | Q494: Yes | R494: Electronic check | S494: 74.4 | T494: 139.4 | U494: Yes
A495: 5756-OZRIO | B495: Male | C495: 1 | D495: Yes | E495: No | F495: 61 | G495: Yes | H495: Yes | I495: DSL | J495: No | K495: Yes | L495: No | M495: No | N495: No | O495: Yes | P495: One year | Q495: No | R495: Bank transfer (automatic) | S495: 64.05 | T495: 3902.6 | U495: No
A496: 6579-JPICP | B496: Male | C496: 0 | D496: No | E496: No | F496: 1 | G496: Yes | H496: No | I496: No | J496: No internet service | K496: No internet service | L496: No internet service | M496: No internet service | N496: No internet service | O496: No internet service | P496: Month-to-month | Q496: No | R496: Mailed check | S496: 20.4 | T496: 20.4 | U496: No
A497: 8205-OTCHB | B497: Male | C497: 0 | D497: No | E497: No | F497: 22 | G497: No | H497: No phone service | I497: DSL | J497: No | K497: Yes | L497: Yes | M497: No | N497: No | O497: Yes | P497: One year | Q497: Yes | R497: Bank transfer (automatic) | S497: 43.75 | T497: 903.6 | U497: Yes
A498: 4134-BSXLX | B498: Male | C498: 0 | D498: Yes | E498: No | F498: 28 | G498: Yes | H498: No | I498: DSL | J498: Yes | K498: Yes | L498: No | M498: Yes | N498: No | O498: No | P498: Month-to-month | Q498: No | R498: Mailed check | S498: 60.9 | T498: 1785.65 | U498: No
A499: 0505-SPOOW | B499: Female | C499: 0 | D499: Yes | E499: No | F499: 70 | G499: Yes | H499: No | I499: No | J499: No internet service | K499: No internet service | L499: No internet service | M499: No internet service | N499: No internet service | O499: No internet service | P499: Two year | Q499: No | R499: Bank transfer (automatic) | S499: 19.8 | T499: 1397.65 | U499: No
A500: 6235-VDHOM | B500: Female | C500: 1 | D500: No | E500: No | F500: 5 | G500: No | H500: No phone service | I500: DSL | J500: No | K500: Yes | L500: No | M500: No | N500: No | O500: No | P500: Month-to-month | Q500: No | R500: Electronic check | S500: 28.45 | T500: 131.05 | U500: Yes
A501: 7783-YKGDV | B501: Female | C501: 0 | D501: No | E501: No | F501: 12 | G501: Yes | H501: Yes | I501: Fiber optic | J501: Yes | K501: Yes | L501: Yes | M501: No | N501: No | O501: Yes | P501: Month-to-month | Q501: Yes | R501: Bank transfer (automatic) | S501: 99.7 | T501: 1238.45 | U501: Yes
A502: 4374-YMUSQ | B502: Male | C502: 0 | D502: No | E502: No | F502: 34 | G502: Yes | H502: Yes | I502: Fiber optic | J502: Yes | K502: Yes | L502: Yes | M502: Yes | N502: Yes | O502: Yes | P502: One year | Q502: No | R502: Credit card (automatic) | S502: 116.25 | T502: 3899.05 | U502: No
... A754: 1410-RSCMR | B754: Male | C754: 0 | D754: Yes | E754: Yes | F754: 7 | G754: Yes | H754: No | I754: DSL | J754: Yes | K754: No | L754: Yes | M754: Yes | N754: No | O754: Yes | P754: Month-to-month | Q754: Yes | R754: Credit card (automatic) | S754: 71.35 | T754: 515.75 | U754: No
A755: 3115-CZMZD | B755: Male | C755: 0 | D755: No | E755: Yes | F755: 0 | G755: Yes | H755: No | I755: No | J755: No internet service | K755: No internet service | L755: No internet service | M755: No internet service | N755: No internet service | O755: No internet service | P755: Two year | Q755: No | R755: Mailed check | S755: 20.25 | U755: No
A756: 0139-IVFJG | B756: Female | C756: 0 | D756: Yes | E756: No | F756: 2 | G756: Yes | H756: No | I756: Fiber optic | J756: Yes | K756: Yes | L756: No | M756: No | N756: Yes | O756: No | P756: Month-to-month | Q756: No | R756: Electronic check | S756: 90.35 | T756: 190.5 | U756: No
A757: 6683-VLCTZ | B757: Male | C757: 1 | D757: No | E757: No | F757: 20 | G757: Yes | H757: Yes | I757: Fiber optic | J757: No | K757: No | L757: Yes | M757: No | N757: Yes | O757: Yes | P757: Month-to-month | Q757: Yes | R757: Electronic check | S757: 98.55 | T757: 1842.8 | U757: Yes
A758: 5730-DBDSI | B758: Male | C758: 0 | D758: No | E758: No | F758: 66 | G758: Yes | H758: No | I758: No | J758: No internet service | K758: No internet service | L758: No internet service | M758: No internet service | N758: No internet service | O758: No internet service | P758: Two year | Q758: No | R758: Bank transfer (automatic) | S758: 19.7 | T758: 1253.8 | U758: No
A759: 0030-FNXPP | B759: Female | C759: 0 | D759: No | E759: No | F759: 3 | G759: Yes | H759: No | I759: No | J759: No internet service | K759: No internet service | L759: No internet service | M759: No internet service | N759: No internet service | O759: No internet service | P759: Month-to-month | Q759: No | R759: Mailed check | S759: 19.85 | T759: 57.2 | U759: No
A760: 2189-WWOEW | B760: Female | C760: 0 | D760: No | E760: Yes | F760: 15 | G760: Yes | H760: No | I760: Fiber optic | J760: No | K760: Yes | L760: No | M760: No | N760: No | O760: Yes | P760: Month-to-month | Q760: Yes | R760: Bank transfer (automatic) | S760: 85.9 | T760: 1269.55 | U760: Yes
A761: 5684-FJVYR | B761: Female | C761: 0 | D761: Yes | E761: Yes | F761: 72 | G761: Yes | H761: Yes | I761: Fiber optic | J761: Yes | K761: Yes | L761: No | M761: Yes | N761: No | O761: No | P761: Two year | Q761: Yes | R761: Bank transfer (automatic) | S761: 90.35 | T761: 6563.4 | U761: No
A762: 4013-GUXND | B762: Male | C762: 0 | D762: No | E762: No | F762: 1 | G762: Yes | H762: No | I762: No | J762: No internet service | K762: No internet service | L762: No internet service | M762: No internet service | N762: No internet service | O762: No internet service | P762: Month-to-month | Q762: No | R762: Mailed check | S762: 20.8 | T762: 20.8 | U762: No
A763: 1894-IGFSG | B763: Female | C763: 0 | D763: No | E763: No | F763: 22 | G763: Yes | H763: No | I763: Fiber optic | J763: No | K763: No | L763: No | M763: No | N763: Yes | O763: Yes | P763: Month-to-month | Q763: No | R763: Electronic check | S763: 89.25 | T763: 1907.85 | U763: Yes
A764: 7379-POKDZ | B764: Male | C764: 0 | D764: Yes | E764: No | F764: 3 | G764: Yes | H764: No | I764: Fiber optic | J764: No | K764: No | L764: No | M764: No | N764: No | O764: No | P764: Month-to-month | Q764: Yes | R764: Electronic check | S764: 70.3 | T764: 208.85 | U764: Yes
A765: 1266-NZYUI | B765: Female | C765: 0 | D765: Yes | E765: Yes | F765: 72 | G765: Yes | H765: Yes | I765: DSL | J765: Yes | K765: No | L765: Yes | M765: Yes | N765: No | O765: No | P765: Two year | Q765: No | R765: Bank transfer (automatic) | S765: 66.85 | T765: 4758.8 | U765: No
A766: 7969-FFOWG | B766: Male | C766: 0 | D766: Yes | E766: Yes | F766: 65 | G766: Yes | H766: No | I766: No | J766: No internet service | K766: No internet service | L766: No internet service | M766: No internet service | N766: No internet service | O766: No internet service | P766: Two year | Q766: No | R766: Mailed check | S766: 19.9 | T766: 1292.6 | U766: No
...

Sheet QA_Checks
A1: Total Rows | B1: Total Columns | C1: Unique Customers | D1: Duplicate customerID? | E1: Missing Values Present? | F1: CustomerID | G1: Duplicate_Flag
A2: =COUNTA(Raw!A:A)-1 -> 7043 | B2: =COUNTA(Raw!1:1) -> 21 | C2: =COUNTIF(G:G,"Unique") -> 7043 | D2: =IF(COUNTIF(G:G,"Duplicate")>0,"Yes","No") -> No | E2: =IF(SUMPRODUCT(--(Raw!A2:U10000=""))>0,"Yes","No") -> Yes | F2: =Raw!A2 -> 7590-VHVEG | G2: =IF(COUNTIF($A:$A,A2)>1,"Duplicate","Unique") -> Unique
F3: =Raw!A3 -> 5575-GNVDE | G3: =IF(COUNTIF($A:$A,A3)>1,"Duplicate","Unique") -> Unique
F4: =Raw!A4 -> 3668-QPYBK | G4: =IF(COUNTIF($A:$A,A4)>1,"Duplicate","Unique") -> Unique
F5: =Raw!A5 -> 7795-CFOCW | G5: =IF(COUNTIF($A:$A,A5)>1,"Duplicate","Unique") -> Unique
F6: =Raw!A6 -> 9237-HQITU | G6: =IF(COUNTIF($A:$A,A6)>1,"Duplicate","Unique") -> Unique
F7: =Raw!A7 -> 9305-CDSKC | G7: =IF(COUNTIF($A:$A,A7)>1,"Duplicate","Unique") -> Unique
F8: =Raw!A8 -> 1452-KIOVK | G8: =IF(COUNTIF($A:$A,A8)>1,"Duplicate","Unique") -> Unique
F9: =Raw!A9 -> 6713-OKOMC | G9: =IF(COUNTIF($A:$A,A9)>1,"Duplicate","Unique") -> Unique
F10: =Raw!A10 -> 7892-POOKP | G10: =IF(COUNTIF($A:$A,A10)>1,"Duplicate","Unique") -> Unique
F11: =Raw!A11 -> 6388-TABGU | G11: =IF(COUNTIF($A:$A,A11)>1,"Duplicate","Unique") -> Unique
F12: =Raw!A12 -> 9763-GRSKD | G12: =IF(COUNTIF($A:$A,A12)>1,"Duplicate","Unique") -> Unique
F13: =Raw!A13 -> 7469-LKBCI | G13: =IF(COUNTIF($A:$A,A13)>1,"Duplicate","Unique") -> Unique
F14: =Raw!A14 -> 8091-TTVAX | G14: =IF(COUNTIF($A:$A,A14)>1,"Duplicate","Unique") -> Unique
... F7044: =Raw!A7044 -> 3186-AJIEK | G7044: =IF(COUNTIF($A:$A,A7044)>1,"Duplicate","Unique") -> Unique
F7047: =Raw!A7047 -> 0
F7048: =Raw!A7048 -> 0
F7049: =Raw!A7049 -> 0
F7050: =Raw!A7050 -> 0
F7051: =Raw!A7051 -> 0
F7052: =Raw!A7052 -> 0
F7053: =Raw!A7053 -> 0
F7054: =Raw!A7054 -> 0
F7055: =Raw!A7055 -> 0
F7056: =Raw!A7056 -> 0
F7057: =Raw!A7057 -> 0
F7058: =Raw!A7058 -> 0
... F7400: =Raw!A7400 -> 0
